<?xml version="1.0" encoding="utf-8"?>
<!-- This URDF was automatically created by SolidWorks to URDF Exporter! Originally created by Stephen Brawner (brawner@gmail.com) 
     Commit Version: 1.6.0-4-g7f85cfe  Build Version: 1.6.7995.38578
     For more information, please see http://wiki.ros.org/sw_urdf_exporter -->
<robot
  name="urdf_UR20_MvS">
  <link
    name="base_link">
    <inertial>
      <origin
        xyz="0 0 0"
        rpy="0 0 0" />
      <mass
        value="0" />
      <inertia
        ixx="0"
        ixy="0"
        ixz="0"
        iyy="0"
        iyz="0"
        izz="0" />
    </inertial>
    <visual>
      <origin
        xyz="0 0 0"
        rpy="0 0 0" />
      <geometry>
        <mesh
          filename="package://urdf_UR20_MvS/meshes/base_link.STL" />
      </geometry>
      <material
        name="">
        <color
          rgba="0.79216 0.81961 0.93333 1" />
      </material>
    </visual>
    <collision>
      <origin
        xyz="0 0 0"
        rpy="0 0 0" />
      <geometry>
        <mesh
          filename="package://urdf_UR20_MvS/meshes/base_link.STL" />
      </geometry>
    </collision>
  </link>
  <link
    name="link_0">
    <inertial>
      <origin
        xyz="0 -0.061 0.0062"
        rpy="0 0 0" />
      <mass
        value="16.343" />
      <inertia
        ixx="0.0887"
        ixy="-0.0001"
        ixz="-0.0001"
        iyy="0.0763"
        iyz="0.0072"
        izz="0.0842" />
    </inertial>
    <visual>
      <origin
        xyz="0 0 0"
        rpy="0 0 0" />
      <geometry>
        <mesh
          filename="package://urdf_UR20_MvS/meshes/link_0.STL" />
      </geometry>
      <material
        name="">
        <color
          rgba="0.79216 0.81961 0.93333 1" />
      </material>
    </visual>
    <collision>
      <origin
        xyz="0 0 0"
        rpy="0 0 0" />
      <geometry>
        <mesh
          filename="package://urdf_UR20_MvS/meshes/link_0.STL" />
      </geometry>
    </collision>
  </link>
  <joint
    name="joint_1"
    type="revolute">
    <origin
      xyz="0 0 0.2363"
      rpy="1.5708 0 1.4242" />
    <parent
      link="base_link" />
    <child
      link="link_0" />
    <axis
      xyz="0 -1 0" />
    <limit
      lower="-6.283"
      upper="6.283"
      effort="20"
      velocity="2.094" />
  </joint>
  <link
    name="link_1">
    <inertial>
      <origin
        xyz="0.5226 0 0.2098"
        rpy="0 0 0" />
      <mass
        value="29.632" />
      <inertia
        ixx="0.1467"
        ixy="0.0002"
        ixz="-0.0516"
        iyy="4.6659"
        iyz="0"
        izz="4.6348" />
    </inertial>
    <visual>
      <origin
        xyz="0 0 0"
        rpy="0 0 0" />
      <geometry>
        <mesh
          filename="package://urdf_UR20_MvS/meshes/link_1.STL" />
      </geometry>
      <material
        name="">
        <color
          rgba="0.79216 0.81961 0.93333 1" />
      </material>
    </visual>
    <collision>
      <origin
        xyz="0 0 0"
        rpy="0 0 0" />
      <geometry>
        <mesh
          filename="package://urdf_UR20_MvS/meshes/link_1.STL" />
      </geometry>
    </collision>
  </link>
  <joint
    name="joint_2"
    type="revolute">
    <origin
      xyz="0.20083 0.83828 0"
      rpy="0 0 -0.21563" />
    <parent
      link="link_0" />
    <child
      link="link_1" />
    <axis
      xyz="0 0 1" />
    <limit
      lower="-6.283"
      upper="6.283"
      effort="20"
      velocity="2.094" />
  </joint>
  <link
    name="link_2">
    <inertial>
      <origin
        xyz="0.3234 0 0.0604"
        rpy="0 0 0" />
      <mass
        value="7.879" />
      <inertia
        ixx="0.0261"
        ixy="-0.0001"
        ixz="-0.029"
        iyy="0.7576"
        iyz="0"
        izz="0.7533" />
    </inertial>
    <visual>
      <origin
        xyz="0 0 0"
        rpy="0 0 0" />
      <geometry>
        <mesh
          filename="package://urdf_UR20_MvS/meshes/link_2.STL" />
      </geometry>
      <material
        name="">
        <color
          rgba="0.79216 0.81961 0.93333 1" />
      </material>
    </visual>
    <collision>
      <origin
        xyz="0 0 0"
        rpy="0 0 0" />
      <geometry>
        <mesh
          filename="package://urdf_UR20_MvS/meshes/link_2.STL" />
      </geometry>
    </collision>
  </link>
  <joint
    name="joint_3"
    type="revolute">
    <origin
      xyz="0 0.7287 0"
      rpy="0 0 -1.5708" />
    <parent
      link="link_1" />
    <child
      link="link_2" />
    <axis
      xyz="0 0 1" />
    <limit
      lower="-6.283"
      upper="6.283"
      effort="20"
      velocity="2.618" />
  </joint>
  <link
    name="link_3">
    <inertial>
      <origin
        xyz="0 -0.0026 0.0393"
        rpy="0 0 0" />
      <mass
        value="3.054" />
      <inertia
        ixx="0.0056"
        ixy="0"
        ixz="0"
        iyy="0.0054"
        iyz="0.0004"
        izz="0.004" />
    </inertial>
    <visual>
      <origin
        xyz="0 0 0"
        rpy="0 0 0" />
      <geometry>
        <mesh
          filename="package://urdf_UR20_MvS/meshes/link_3.STL" />
      </geometry>
      <material
        name="">
        <color
          rgba="0.79216 0.81961 0.93333 1" />
      </material>
    </visual>
    <collision>
      <origin
        xyz="0 0 0"
        rpy="0 0 0" />
      <geometry>
        <mesh
          filename="package://urdf_UR20_MvS/meshes/link_3.STL" />
      </geometry>
    </collision>
  </link>
  <joint
    name="joint_4"
    type="revolute">
    <origin
      xyz="0 0 0.201"
      rpy="1.5708 0 -1.6575" />
    <parent
      link="link_2" />
    <child
      link="link_3" />
    <axis
      xyz="0 -1 0" />
    <limit
      lower="-6.283"
      upper="6.283"
      effort="20"
      velocity="3.665" />
  </joint>
  <link
    name="link_4">
    <inertial>
      <origin
        xyz="0 0.0024 0.0379"
        rpy="0 0 0" />
      <mass
        value="3.126" />
      <inertia
        ixx="0.0059"
        ixy="0"
        ixz="0"
        iyy="0.0058"
        iyz="-0.0004"
        izz="0.0043" />
    </inertial>
    <visual>
      <origin
        xyz="0 0 0"
        rpy="0 0 0" />
      <geometry>
        <mesh
          filename="package://urdf_UR20_MvS/meshes/link_4.STL" />
      </geometry>
      <material
        name="">
        <color
          rgba="0.79216 0.81961 0.93333 1" />
      </material>
    </visual>
    <collision>
      <origin
        xyz="0 0 0"
        rpy="0 0 0" />
      <geometry>
        <mesh
          filename="package://urdf_UR20_MvS/meshes/link_4.STL" />
      </geometry>
    </collision>
  </link>
  <joint
    name="joint_5"
    type="revolute">
    <origin
      xyz="0 0 0.1593"
      rpy="-1.5708 0 -0.32244" />
    <parent
      link="link_3" />
    <child
      link="link_4" />
    <axis
      xyz="0 1 0" />
    <limit
      lower="-6.283"
      upper="6.283"
      effort="20"
      velocity="3.665" />
  </joint>
  <link
    name="link_5">
    <inertial>
      <origin
        xyz="0 -0.0003 -0.0318"
        rpy="0 0 0" />
      <mass
        value="0.846" />
      <inertia
        ixx="0.0009"
        ixy="0"
        ixz="0"
        iyy="0.0009"
        iyz="0"
        izz="0.0012" />
    </inertial>
    <visual>
      <origin
        xyz="0 0 0"
        rpy="0 0 0" />
      <geometry>
        <mesh
          filename="package://urdf_UR20_MvS/meshes/link_5.STL" />
      </geometry>
      <material
        name="">
        <color
          rgba="0.79216 0.81961 0.93333 1" />
      </material>
    </visual>
    <collision>
      <origin
        xyz="0 0 0"
        rpy="0 0 0" />
      <geometry>
        <mesh
          filename="package://urdf_UR20_MvS/meshes/link_5.STL" />
      </geometry>
    </collision>
  </link>
  <joint
    name="joint_6"
    type="revolute">
    <origin
      xyz="0 0 0.1543"
      rpy="0 0 -0.19583" />
    <parent
      link="link_4" />
    <child
      link="link_5" />
    <axis
      xyz="0 0 -1" />
    <limit
      lower="-6.283"
      upper="6.283"
      effort="20"
      velocity="3.665" />
  </joint>
</robot>
